 * Serving Flask app 'app'
 * Debug mode: on
[31m[1mWARNING: This is a development server. Do not use it in a production deployment. Use a production WSGI server instead.[0m
 * Running on all addresses (0.0.0.0)
 * Running on http://127.0.0.1:5000
 * Running on http://192.168.0.2:5000
[33mPress CTRL+C to quit[0m
 * Restarting with stat
 * Debugger is active!
 * Debugger PIN: 148-452-288
[2025-08-25 10:15:08,075] ERROR in app: Failed to emit event user.created: HTTPConnectionPool(host='localhost', port=5007): Max retries exceeded with url: /events/ingest (Caused by NewConnectionError('<urllib3.connection.HTTPConnection object at 0x7f410ef2cce0>: Failed to establish a new connection: [Errno 111] Connection refused'))
[2025-08-25 10:15:08,079] INFO in app: OTP for test@example.com: 530939
[2025-08-25 10:15:08,081] WARNING in app: Could not send OTP email to test@example.com (credentials might be missing): Unable to locate credentials
127.0.0.1 - - [25/Aug/2025 10:15:08] "POST /auth/request-otp HTTP/1.1" 200 -
